<?xml version="1.0"?>

<robot xmlns:xacro="http://www.ros.org/wiki/xacro" name="machine2"> 
    <!-- LAUNCH: ros2 launch urdf_tutorial display.launch.py model:=/home/marvin/machine2_ws/src/machine2_description/urdf/machine2.urdf.xacro -->

    <!-- PROPERTIES = VARIABLES -->
    <xacro:property name="PI" value="3.14159"/>
    <xacro:property name="effort" value="1000.0"/>
    <xacro:property name="velocity" value="2.5"/>

    <!-- MACROS = FUNCTIONS -->

    <!-- LINKS -->
    <link name="world"/>

    <link name="base_link">
        <visual>
            <origin xyz="0 0 ${0.25 / 2}" rpy="0 0 0"/>
            <geometry>
                <!-- length, width, height in meters -->
                <box size="0.02 0.02 0.25" />
            </geometry>
            <material name="grey">
                <color rgba="0.5 0.5 0.5 1" />
            </material>
        </visual>
    </link>

    <link name="shoulder_link">
        <visual>
            <origin xyz="0 0 ${0.065 / 2}" rpy="0 0 0"/>
            <geometry>
                <!-- length, width, height in meters -->
                <box size="0.055 0.025 0.065" />
            </geometry>
        </visual>
    </link>

    <link name="shoulder_y_link">
        <visual>
            <origin xyz="0 0 0" rpy="0 0 0"/>
            <geometry>
                <box size="0.055 0.055 0.025" />
            </geometry>
            <material name="blue">
                <color rgba="0 0 0.5 1" />
            </material>
        </visual>
    </link>

    <link name="shoulder_x_link">
        <visual>
            <origin xyz="0 0 ${0.13 / 2}" rpy="0 0 0"/>
            <geometry>
                <box size="0.025 0.055 0.13" />
            </geometry>
        </visual>
    </link>

    <link name="knee_link">
        <visual>
            <origin xyz="0 0 ${0.13 / 2}" rpy="0 0 0"/>
            <geometry>
                <box size="0.055 0.025 0.15" />
            </geometry>
            <material name="blue">
                <color rgba="0 0 0.5 1" />
            </material>
        </visual>
    </link>

    <!-- JOINTS -->
    <joint name="virtual_joint" type="fixed">
        <parent link="world"/>
        <child link="base_link"/>
        <origin xyz="0 0 0" rpy="0 0 0"/>
    </joint>

    <joint name="shoulder_joint" type="fixed">
        <parent link="base_link"/>
        <child link="shoulder_link"/>
        <origin xyz="0 0 0.25" rpy="0 -${PI / 2} 0"/>
    </joint>

    <joint name="shoulder_y_axis_joint" type="revolute">
        <parent link="shoulder_link"/>
        <child link="shoulder_y_link"/>
        <axis xyz="1.0 0 0"/>
        <origin xyz="0 0 ${0.065 - 0.025 / 2}" rpy="0 0 0"/>
        <limit lower="-${PI / 2}" upper="${PI / 2}" effort="${effort}" velocity="${velocity}"/>
    </joint>

    <joint name="shoulder_x_axis_joint" type="revolute">
        <parent link="shoulder_y_link"/>
        <child link="shoulder_x_link"/>
        <axis xyz="0 1.0 0"/>
        <origin xyz="0 0 ${0.025 / 2}" rpy="0 0 0"/>
        <limit lower="-${PI / 2}" upper="${PI / 2}" effort="${effort}" velocity="${velocity}"/>
    </joint>

    <joint name="knee_joint" type="revolute">
        <parent link="shoulder_x_link"/>
        <child link="knee_link"/>
        <axis xyz="0 1.0 0"/>
        <origin xyz="0 0 0.13" rpy="0 0 0"/>
        <limit lower="-${PI / 2 + PI / 4}" upper="0" effort="${effort}" velocity="${velocity}"/>
    </joint>

    <!-- ROS CONTROL DESCRIPTION -->
    <ros2_control name="FullRobotSystem" type="system">

        <hardware>
            <!-- plugin self-defined in machine2_hardware_interfaces machine2_controller.cpp -->
            <!-- here we load hardware interfaces and then the controller loads this urdf -->
            <plugin>machine_hardware_interface/MachineSystem</plugin>
        </hardware>

        <joint name="shoulder_y_axis_joint">
            <command_interface name="position">
                <param name="min">-${PI / 2}</param>
                <param name="max">${PI / 2}</param>
            </command_interface>
            <command_interface name="velocity">
                <param name="min">-3.15</param>
                <param name="max">3.15</param>
            </command_interface>
            <state_interface name="position">
                <param name="initial_value">0.0</param>
            </state_interface>
            <state_interface name="velocity"/>
        </joint>

        <joint name="shoulder_x_axis_joint">
            <command_interface name="position">
                <param name="min">-${PI / 2}</param>
                <param name="max">${PI / 2}</param>
            </command_interface>
            <command_interface name="velocity">
                <param name="min">-3.15</param>
                <param name="max">3.15</param>
            </command_interface>
            <state_interface name="position">
                <param name="initial_value">0.0</param>
            </state_interface>
            <state_interface name="velocity"/>
        </joint>

        <joint name="knee_joint">
            <command_interface name="position">
                <param name="min">-${PI / 2 + PI / 4}</param>
                <param name="max">0.0</param>
            </command_interface>
            <command_interface name="velocity">
                <param name="min">-3.15</param>
                <param name="max">3.15</param>
            </command_interface>
            <state_interface name="position">
                <param name="initial_value">0.0</param>
            </state_interface>
            <state_interface name="velocity"/>
        </joint>

    </ros2_control>

</robot>